2024-05-07 12:50:22 | INFO    | __main__:stash:131 | run - {'image': '20231121', 'version': '0.10.1.post2', 'role': 'EpicPlayer', 'headless': True}
2024-05-07 12:50:26 | WARNING    | epic_games.agent:get_order_history:467 | Failed to get order history, cookie may have expired - {}
2024-05-07 12:50:26 | DEBUG    | __main__:create_tasks:66 | Put task - {'title': 'Orcs Must Die! 3', 'url': 'https://store.epicgames.com/en-US/p/combo-a7e03a'}
2024-05-07 12:50:26 | DEBUG    | __main__:create_tasks:66 | Put task - {'title': 'Cat Quest II', 'url': 'https://store.epicgames.com/en-US/p/cat-quest-ii-9dbefc'}
2024-05-07 12:50:31 | INFO    | epic_games.agent:claim_weekly_games:294 | claim_weekly_games - {'action': 'go to store', 'url': 'https://store.epicgames.com/en-US/p/combo-a7e03a'}
2024-05-07 12:50:42 | ERROR    | __main__:run:158 | An error has been caught in function 'run', process 'MainProcess' (3784), thread 'MainThread' (139820345121664): - {}
Traceback (most recent call last):
  File "/home/runner/work/HI-plus/HI-plus/epic/src/claim.py", line 162, in <module>
    asyncio.run(run())
  File "/opt/hostedtoolcache/Python/3.10.14/x64/lib/python3.10/asyncio/runners.py", line 44, in run
    return loop.run_until_complete(main)
  File "/opt/hostedtoolcache/Python/3.10.14/x64/lib/python3.10/asyncio/base_events.py", line 636, in run_until_complete
    self.run_forever()
  File "/opt/hostedtoolcache/Python/3.10.14/x64/lib/python3.10/asyncio/base_events.py", line 603, in run_forever
    self._run_once()
  File "/opt/hostedtoolcache/Python/3.10.14/x64/lib/python3.10/asyncio/base_events.py", line 1909, in _run_once
    handle._run()
  File "/opt/hostedtoolcache/Python/3.10.14/x64/lib/python3.10/asyncio/events.py", line 80, in _run
    self._context.run(self._callback, *self._args)
> File "/home/runner/work/HI-plus/HI-plus/epic/src/claim.py", line 158, in run
    await agent.stash()
  File "/home/runner/work/HI-plus/HI-plus/epic/src/claim.py", line 151, in stash
    await self.claim_epic_games(context)
  File "/home/runner/work/HI-plus/HI-plus/epic/src/claim.py", line 122, in claim_epic_games
    await epic.claim_weekly_games(page, single_promotions)
  File "/opt/hostedtoolcache/Python/3.10.14/x64/lib/python3.10/site-packages/tenacity/_asyncio.py", line 88, in async_wrapped
    return await fn(*args, **kwargs)
  File "/opt/hostedtoolcache/Python/3.10.14/x64/lib/python3.10/site-packages/tenacity/_asyncio.py", line 47, in __call__
    do = self.iter(retry_state=retry_state)
  File "/opt/hostedtoolcache/Python/3.10.14/x64/lib/python3.10/site-packages/tenacity/__init__.py", line 314, in iter
    return fut.result()
  File "/opt/hostedtoolcache/Python/3.10.14/x64/lib/python3.10/concurrent/futures/_base.py", line 451, in result
    return self.__get_result()
  File "/opt/hostedtoolcache/Python/3.10.14/x64/lib/python3.10/concurrent/futures/_base.py", line 403, in __get_result
    raise self._exception
  File "/opt/hostedtoolcache/Python/3.10.14/x64/lib/python3.10/site-packages/tenacity/_asyncio.py", line 50, in __call__
    result = await fn(*args, **kwargs)
  File "/home/runner/work/HI-plus/HI-plus/epic/src/epic_games/agent.py", line 310, in claim_weekly_games
    await expect(cta_btn).to_have_text("View In Cart")
  File "/opt/hostedtoolcache/Python/3.10.14/x64/lib/python3.10/site-packages/playwright/async_api/_generated.py", line 18871, in to_have_text
    await self._impl_obj.to_have_text(
  File "/opt/hostedtoolcache/Python/3.10.14/x64/lib/python3.10/site-packages/playwright/_impl/_assertions.py", line 471, in to_have_text
    await self._expect_impl(
  File "/opt/hostedtoolcache/Python/3.10.14/x64/lib/python3.10/site-packages/playwright/_impl/_assertions.py", line 70, in _expect_impl
    raise AssertionError(
AssertionError: Locator expected to have text 'View In Cart'
Actual value: None 
Call log:
LocatorAssertions.to_have_text with timeout 5000ms
  - waiting for locator("//aside//button[@data-testid='add-to-cart-cta-button']")

