{"text": "2024-02-25 12:50:24 | INFO    | __main__:stash:131 | run - {'image': '20231121', 'version': '0.10.1.post2', 'role': 'EpicPlayer', 'headless': True}\n", "record": {"elapsed": {"repr": "0:00:01.435254", "seconds": 1.435254}, "exception": null, "extra": {"image": "20231121", "version": "0.10.1.post2", "role": "EpicPlayer", "headless": true}, "file": {"name": "claim.py", "path": "/home/runner/work/HI-plus/HI-plus/epic/src/claim.py"}, "function": "stash", "level": {"icon": "ℹ️", "name": "INFO", "no": 20}, "line": 131, "message": "run", "module": "claim", "name": "__main__", "process": {"id": 3556, "name": "MainProcess"}, "thread": {"id": 139923464510336, "name": "MainThread"}, "time": {"repr": "2024-02-25 12:50:24.071437+08:00", "timestamp": 1708836624.071437}}}
{"text": "2024-02-25 12:50:55 | ERROR    | __main__:run:158 | An error has been caught in function 'run', process 'MainProcess' (3556), thread 'MainThread' (139923464510336): - {}\nTraceback (most recent call last):\n  File \"/home/runner/work/HI-plus/HI-plus/epic/src/claim.py\", line 162, in <module>\n    asyncio.run(run())\n  File \"/opt/hostedtoolcache/Python/3.10.13/x64/lib/python3.10/asyncio/runners.py\", line 44, in run\n    return loop.run_until_complete(main)\n  File \"/opt/hostedtoolcache/Python/3.10.13/x64/lib/python3.10/asyncio/base_events.py\", line 636, in run_until_complete\n    self.run_forever()\n  File \"/opt/hostedtoolcache/Python/3.10.13/x64/lib/python3.10/asyncio/base_events.py\", line 603, in run_forever\n    self._run_once()\n  File \"/opt/hostedtoolcache/Python/3.10.13/x64/lib/python3.10/asyncio/base_events.py\", line 1909, in _run_once\n    handle._run()\n  File \"/opt/hostedtoolcache/Python/3.10.13/x64/lib/python3.10/asyncio/events.py\", line 80, in _run\n    self._context.run(self._callback, *self._args)\n> File \"/home/runner/work/HI-plus/HI-plus/epic/src/claim.py\", line 158, in run\n    await agent.stash()\n  File \"/home/runner/work/HI-plus/HI-plus/epic/src/claim.py\", line 149, in stash\n    if not await self.prelude_with_context(context):\n  File \"/home/runner/work/HI-plus/HI-plus/epic/src/claim.py\", line 73, in prelude_with_context\n    await page.goto(url, wait_until=\"networkidle\")\n  File \"/opt/hostedtoolcache/Python/3.10.13/x64/lib/python3.10/site-packages/playwright/async_api/_generated.py\", line 9275, in goto\n    await self._impl_obj.goto(\n  File \"/opt/hostedtoolcache/Python/3.10.13/x64/lib/python3.10/site-packages/playwright/_impl/_page.py\", line 484, in goto\n    return await self._main_frame.goto(**locals_to_params(locals()))\n  File \"/opt/hostedtoolcache/Python/3.10.13/x64/lib/python3.10/site-packages/playwright/_impl/_frame.py\", line 149, in goto\n    await self._channel.send(\"goto\", locals_to_params(locals()))\n  File \"/opt/hostedtoolcache/Python/3.10.13/x64/lib/python3.10/site-packages/playwright/_impl/_connection.py\", line 63, in send\n    return await self._connection.wrap_api_call(\n  File \"/opt/hostedtoolcache/Python/3.10.13/x64/lib/python3.10/site-packages/playwright/_impl/_connection.py\", line 495, in wrap_api_call\n    return await cb()\n  File \"/opt/hostedtoolcache/Python/3.10.13/x64/lib/python3.10/site-packages/playwright/_impl/_connection.py\", line 101, in inner_send\n    result = next(iter(done)).result()\nplaywright._impl._errors.TimeoutError: Timeout 30000ms exceeded.\n", "record": {"elapsed": {"repr": "0:00:33.288353", "seconds": 33.288353}, "exception": {"type": "TimeoutError", "value": "Timeout 30000ms exceeded.", "traceback": true}, "extra": {}, "file": {"name": "claim.py", "path": "/home/runner/work/HI-plus/HI-plus/epic/src/claim.py"}, "function": "run", "level": {"icon": "❌", "name": "ERROR", "no": 40}, "line": 158, "message": "An error has been caught in function 'run', process 'MainProcess' (3556), thread 'MainThread' (139923464510336):", "module": "claim", "name": "__main__", "process": {"id": 3556, "name": "MainProcess"}, "thread": {"id": 139923464510336, "name": "MainThread"}, "time": {"repr": "2024-02-25 12:50:55.924536+08:00", "timestamp": 1708836655.924536}}}
